No exception
I am inside finally
Test completed
